Traceback (most recent call last):
  File "/home/runner/.virtualenvs/.venv/lib/python3.10/site-packages/google/cloud/bigquery/client.py", line 2447, in load_table_from_file
    response = self._do_resumable_upload(
  File "/home/runner/.virtualenvs/.venv/lib/python3.10/site-packages/google/cloud/bigquery/client.py", line 2864, in _do_resumable_upload
    upload, transport = self._initiate_resumable_upload(
  File "/home/runner/.virtualenvs/.venv/lib/python3.10/site-packages/google/cloud/bigquery/client.py", line 2937, in _initiate_resumable_upload
    upload.initiate(
  File "/home/runner/.virtualenvs/.venv/lib/python3.10/site-packages/google/resumable_media/requests/upload.py", line 420, in initiate
    return _request_helpers.wait_and_retry(
  File "/home/runner/.virtualenvs/.venv/lib/python3.10/site-packages/google/resumable_media/requests/_request_helpers.py", line 148, in wait_and_retry
    response = func()
  File "/home/runner/.virtualenvs/.venv/lib/python3.10/site-packages/google/resumable_media/requests/upload.py", line 416, in retriable_request
    self._process_initiate_response(result)
  File "/home/runner/.virtualenvs/.venv/lib/python3.10/site-packages/google/resumable_media/_upload.py", line 509, in _process_initiate_response
    _helpers.require_status_code(
  File "/home/runner/.virtualenvs/.venv/lib/python3.10/site-packages/google/resumable_media/_helpers.py", line 105, in require_status_code
    raise common.InvalidResponse(
google.resumable_media.common.InvalidResponse: ('Request failed with status code', 404, 'Expected one of', <HTTPStatus.OK: 200>, <HTTPStatus.CREATED: 201>)

During handling of the above exception, another exception occurred:

Traceback (most recent call last):
  File "/home/runner/.virtualenvs/.venv/lib/python3.10/site-packages/dlt/load/bigquery/client.py", line 203, in start_file_load
    self._create_load_job(table["name"], table["write_disposition"], file_path),
  File "/home/runner/.virtualenvs/.venv/lib/python3.10/site-packages/dlt/load/bigquery/client.py", line 308, in _create_load_job
    return self.sql_client.native_connection.load_table_from_file(f,
  File "/home/runner/.virtualenvs/.venv/lib/python3.10/site-packages/google/cloud/bigquery/client.py", line 2455, in load_table_from_file
    raise exceptions.from_http_response(exc.response)
google.api_core.exceptions.NotFound: 404 POST https://bigquery.googleapis.com/upload/bigquery/v2/projects/axies-ronin-pipeline/jobs?uploadType=resumable: Not found: Table axies-ronin-pipeline:axies_github_1.katana_router_contract_call_add_liquidity_ron was not found in location US

During handling of the above exception, another exception occurred:

Traceback (most recent call last):
  File "/home/runner/.virtualenvs/.venv/lib/python3.10/site-packages/dlt/load/load.py", line 99, in w_spool_job
    job = client.start_file_load(table, self.load_storage.storage._make_path(file_path))
  File "/home/runner/.virtualenvs/.venv/lib/python3.10/site-packages/dlt/load/bigquery/client.py", line 208, in start_file_load
    raise LoadUnknownTableException(table["name"], file_path)
dlt.load.exceptions.LoadUnknownTableException: Client does not know table katana_router_contract_call_add_liquidity_ron for load file /home/runner/work/dlt-axie-infinity-demo/dlt-axie-infinity-demo/.pipeline/normalized/normalized/1662132119.220273/new_jobs/katana_router_contract_call_add_liquidity_ron.2848ab9b64891728217b0c5138ddca45.jsonl
